2025-10-10 20:03:41.866 | [2025-10-11 01:03:41 +0000] [1] [INFO] Starting gunicorn 23.0.0
2025-10-10 20:03:41.868 | [2025-10-11 01:03:41 +0000] [1] [INFO] Listening at: http://0.0.0.0:5000 (1)
2025-10-10 20:03:41.868 | [2025-10-11 01:03:41 +0000] [1] [INFO] Using worker: sync
2025-10-10 20:03:41.890 | [2025-10-11 01:03:41 +0000] [6] [INFO] Booting worker with pid: 6
2025-10-10 20:03:41.933 | [2025-10-11 01:03:41 +0000] [7] [INFO] Booting worker with pid: 7
2025-10-10 20:03:41.989 | [2025-10-11 01:03:41 +0000] [8] [INFO] Booting worker with pid: 8
2025-10-10 20:03:42.054 | [2025-10-11 01:03:42 +0000] [9] [INFO] Booting worker with pid: 9
2025-10-10 20:03:43.694 | /usr/local/lib/python3.11/site-packages/flask_session/redis/redis.py:51: RuntimeWarning: No valid Redis instance provided, attempting to create a new instance on localhost with default settings.
2025-10-10 20:03:43.694 |   warnings.warn(
2025-10-10 20:03:43.920 | /usr/local/lib/python3.11/site-packages/flask_session/redis/redis.py:51: RuntimeWarning: No valid Redis instance provided, attempting to create a new instance on localhost with default settings.
2025-10-10 20:03:43.921 |   warnings.warn(
2025-10-10 20:03:44.397 | /usr/local/lib/python3.11/site-packages/flask_session/redis/redis.py:51: RuntimeWarning: No valid Redis instance provided, attempting to create a new instance on localhost with default settings.
2025-10-10 20:03:44.397 |   warnings.warn(
2025-10-10 20:03:44.437 | /usr/local/lib/python3.11/site-packages/flask_session/redis/redis.py:51: RuntimeWarning: No valid Redis instance provided, attempting to create a new instance on localhost with default settings.
2025-10-10 20:03:44.437 |   warnings.warn(
2025-10-10 20:03:54.550 | [2025-10-11 01:03:54 +0000] [6] [ERROR] Error handling request /
2025-10-10 20:03:54.550 | Traceback (most recent call last):
2025-10-10 20:03:54.550 |   File "/usr/local/lib/python3.11/site-packages/redis/connection.py", line 389, in connect_check_health
2025-10-10 20:03:54.550 |     sock = self.retry.call_with_retry(
2025-10-10 20:03:54.550 |            ^^^^^^^^^^^^^^^^^^^^^^^^^^^
2025-10-10 20:03:54.550 |   File "/usr/local/lib/python3.11/site-packages/redis/retry.py", line 105, in call_with_retry
2025-10-10 20:03:54.550 |     return do()
2025-10-10 20:03:54.550 |            ^^^^
2025-10-10 20:03:54.550 |   File "/usr/local/lib/python3.11/site-packages/redis/connection.py", line 390, in <lambda>
2025-10-10 20:03:54.550 |     lambda: self._connect(), lambda error: self.disconnect(error)
2025-10-10 20:03:54.550 |             ^^^^^^^^^^^^^^^
2025-10-10 20:03:54.550 |   File "/usr/local/lib/python3.11/site-packages/redis/connection.py", line 803, in _connect
2025-10-10 20:03:54.550 |     raise err
2025-10-10 20:03:54.550 |   File "/usr/local/lib/python3.11/site-packages/redis/connection.py", line 787, in _connect
2025-10-10 20:03:54.551 |     sock.connect(socket_address)
2025-10-10 20:03:54.551 | ConnectionRefusedError: [Errno 111] Connection refused
2025-10-10 20:03:54.551 | 
2025-10-10 20:03:54.551 | During handling of the above exception, another exception occurred:
2025-10-10 20:03:54.551 | 
2025-10-10 20:03:54.551 | Traceback (most recent call last):
2025-10-10 20:03:54.551 |   File "/usr/local/lib/python3.11/site-packages/gunicorn/workers/sync.py", line 134, in handle
2025-10-10 20:03:54.551 |     self.handle_request(listener, req, client, addr)
2025-10-10 20:03:54.551 |   File "/usr/local/lib/python3.11/site-packages/gunicorn/workers/sync.py", line 177, in handle_request
2025-10-10 20:03:54.551 |     respiter = self.wsgi(environ, resp.start_response)
2025-10-10 20:03:54.551 |                ^^^^^^^^^^^^^^^^^^^^^^^^^^^^^^^^^^^^^^^
2025-10-10 20:03:54.551 |   File "/usr/local/lib/python3.11/site-packages/flask/app.py", line 1536, in __call__
2025-10-10 20:03:54.551 |     return self.wsgi_app(environ, start_response)
2025-10-10 20:03:54.551 |            ^^^^^^^^^^^^^^^^^^^^^^^^^^^^^^^^^^^^^^
2025-10-10 20:03:54.551 |   File "/usr/local/lib/python3.11/site-packages/flask_socketio/__init__.py", line 42, in __call__
2025-10-10 20:03:54.551 |     return super().__call__(environ, start_response)
2025-10-10 20:03:54.551 |            ^^^^^^^^^^^^^^^^^^^^^^^^^^^^^^^^^^^^^^^^^
2025-10-10 20:03:54.551 |   File "/usr/local/lib/python3.11/site-packages/engineio/middleware.py", line 74, in __call__
2025-10-10 20:03:54.551 |     return self.wsgi_app(environ, start_response)
2025-10-10 20:03:54.551 |            ^^^^^^^^^^^^^^^^^^^^^^^^^^^^^^^^^^^^^^
2025-10-10 20:03:54.551 |   File "/usr/local/lib/python3.11/site-packages/flask/app.py", line 1514, in wsgi_app
2025-10-10 20:03:54.551 |     response = self.handle_exception(e)
2025-10-10 20:03:54.551 |                ^^^^^^^^^^^^^^^^^^^^^^^^
2025-10-10 20:03:54.551 |   File "/usr/local/lib/python3.11/site-packages/flask_cors/extension.py", line 176, in wrapped_function
2025-10-10 20:03:54.551 |     return cors_after_request(app.make_response(f(*args, **kwargs)))
2025-10-10 20:03:54.551 |                                                 ^^^^^^^^^^^^^^^^^^
2025-10-10 20:03:54.551 |   File "/usr/local/lib/python3.11/site-packages/flask/app.py", line 1510, in wsgi_app
2025-10-10 20:03:54.551 |     ctx.push()
2025-10-10 20:03:54.551 |   File "/usr/local/lib/python3.11/site-packages/flask/ctx.py", line 386, in push
2025-10-10 20:03:54.551 |     self.session = session_interface.open_session(self.app, self.request)
2025-10-10 20:03:54.551 |                    ^^^^^^^^^^^^^^^^^^^^^^^^^^^^^^^^^^^^^^^^^^^^^^^^^^^^^^
2025-10-10 20:03:54.551 |   File "/usr/local/lib/python3.11/site-packages/flask_session/base.py", line 350, in open_session
2025-10-10 20:03:54.551 |     saved_session_data = self._retrieve_session_data(store_id)
2025-10-10 20:03:54.551 |                          ^^^^^^^^^^^^^^^^^^^^^^^^^^^^^^^^^^^^^
2025-10-10 20:03:54.551 |   File "/usr/local/lib/python3.11/site-packages/flask_session/redis/redis.py", line 64, in _retrieve_session_data
2025-10-10 20:03:54.551 |     serialized_session_data = self.client.get(store_id)
2025-10-10 20:03:54.551 |                               ^^^^^^^^^^^^^^^^^^^^^^^^^
2025-10-10 20:03:54.551 |   File "/usr/local/lib/python3.11/site-packages/redis/commands/core.py", line 1829, in get
2025-10-10 20:03:54.551 |     return self.execute_command("GET", name, keys=[name])
2025-10-10 20:03:54.551 |            ^^^^^^^^^^^^^^^^^^^^^^^^^^^^^^^^^^^^^^^^^^^^^^
2025-10-10 20:03:54.551 |   File "/usr/local/lib/python3.11/site-packages/redis/client.py", line 621, in execute_command
2025-10-10 20:03:54.551 |     return self._execute_command(*args, **options)
2025-10-10 20:03:54.551 |            ^^^^^^^^^^^^^^^^^^^^^^^^^^^^^^^^^^^^^^^
2025-10-10 20:03:54.551 |   File "/usr/local/lib/python3.11/site-packages/redis/client.py", line 627, in _execute_command
2025-10-10 20:03:54.551 |     conn = self.connection or pool.get_connection()
2025-10-10 20:03:54.551 |                               ^^^^^^^^^^^^^^^^^^^^^
2025-10-10 20:03:54.551 |   File "/usr/local/lib/python3.11/site-packages/redis/utils.py", line 195, in wrapper
2025-10-10 20:03:54.551 |     return func(*args, **kwargs)
2025-10-10 20:03:54.551 |            ^^^^^^^^^^^^^^^^^^^^^
2025-10-10 20:03:54.551 |   File "/usr/local/lib/python3.11/site-packages/redis/connection.py", line 1533, in get_connection
2025-10-10 20:03:54.551 |     connection.connect()
2025-10-10 20:03:54.551 |   File "/usr/local/lib/python3.11/site-packages/redis/connection.py", line 380, in connect
2025-10-10 20:03:54.551 |     self.connect_check_health(check_health=True)
2025-10-10 20:03:54.551 |   File "/usr/local/lib/python3.11/site-packages/redis/connection.py", line 397, in connect_check_health
2025-10-10 20:03:54.551 |     raise ConnectionError(self._error_message(e))
2025-10-10 20:03:54.551 | redis.exceptions.ConnectionError: Error 111 connecting to localhost:6379. Connection refused.
2025-10-10 20:03:59.944 | [2025-10-11 01:03:59 +0000] [6] [ERROR] Error handling request /.well-known/appspecific/com.chrome.devtools.json
2025-10-10 20:03:59.945 | Traceback (most recent call last):
2025-10-10 20:03:59.945 |   File "/usr/local/lib/python3.11/site-packages/redis/connection.py", line 389, in connect_check_health
2025-10-10 20:03:59.945 |     sock = self.retry.call_with_retry(
2025-10-10 20:03:59.945 |            ^^^^^^^^^^^^^^^^^^^^^^^^^^^
2025-10-10 20:03:59.945 |   File "/usr/local/lib/python3.11/site-packages/redis/retry.py", line 105, in call_with_retry
2025-10-10 20:03:59.945 |     return do()
2025-10-10 20:03:59.945 |            ^^^^
2025-10-10 20:03:59.945 |   File "/usr/local/lib/python3.11/site-packages/redis/connection.py", line 390, in <lambda>
2025-10-10 20:03:59.945 |     lambda: self._connect(), lambda error: self.disconnect(error)
2025-10-10 20:03:59.945 |             ^^^^^^^^^^^^^^^
2025-10-10 20:03:59.945 |   File "/usr/local/lib/python3.11/site-packages/redis/connection.py", line 803, in _connect
2025-10-10 20:03:59.945 |     raise err
2025-10-10 20:03:59.945 |   File "/usr/local/lib/python3.11/site-packages/redis/connection.py", line 787, in _connect
2025-10-10 20:03:59.945 |     sock.connect(socket_address)
2025-10-10 20:03:59.945 | ConnectionRefusedError: [Errno 111] Connection refused
2025-10-10 20:03:59.945 | 
2025-10-10 20:03:59.945 | During handling of the above exception, another exception occurred:
2025-10-10 20:03:59.945 | 
2025-10-10 20:03:59.945 | Traceback (most recent call last):
2025-10-10 20:03:59.945 |   File "/usr/local/lib/python3.11/site-packages/gunicorn/workers/sync.py", line 134, in handle
2025-10-10 20:03:59.945 |     self.handle_request(listener, req, client, addr)
2025-10-10 20:03:59.945 |   File "/usr/local/lib/python3.11/site-packages/gunicorn/workers/sync.py", line 177, in handle_request
2025-10-10 20:03:59.945 |     respiter = self.wsgi(environ, resp.start_response)
2025-10-10 20:03:59.945 |                ^^^^^^^^^^^^^^^^^^^^^^^^^^^^^^^^^^^^^^^
2025-10-10 20:03:59.945 |   File "/usr/local/lib/python3.11/site-packages/flask/app.py", line 1536, in __call__
2025-10-10 20:03:59.945 |     return self.wsgi_app(environ, start_response)
2025-10-10 20:03:59.945 |            ^^^^^^^^^^^^^^^^^^^^^^^^^^^^^^^^^^^^^^
2025-10-10 20:03:59.945 |   File "/usr/local/lib/python3.11/site-packages/flask_socketio/__init__.py", line 42, in __call__
2025-10-10 20:03:59.945 |     return super().__call__(environ, start_response)
2025-10-10 20:03:59.945 |            ^^^^^^^^^^^^^^^^^^^^^^^^^^^^^^^^^^^^^^^^^
2025-10-10 20:03:59.945 |   File "/usr/local/lib/python3.11/site-packages/engineio/middleware.py", line 74, in __call__
2025-10-10 20:03:59.945 |     return self.wsgi_app(environ, start_response)
2025-10-10 20:03:59.945 |            ^^^^^^^^^^^^^^^^^^^^^^^^^^^^^^^^^^^^^^
2025-10-10 20:03:59.945 |   File "/usr/local/lib/python3.11/site-packages/flask/app.py", line 1514, in wsgi_app
2025-10-10 20:03:59.945 |     response = self.handle_exception(e)
2025-10-10 20:03:59.945 |                ^^^^^^^^^^^^^^^^^^^^^^^^
2025-10-10 20:03:59.945 |   File "/usr/local/lib/python3.11/site-packages/flask_cors/extension.py", line 176, in wrapped_function
2025-10-10 20:03:59.945 |     return cors_after_request(app.make_response(f(*args, **kwargs)))
2025-10-10 20:03:59.945 |                                                 ^^^^^^^^^^^^^^^^^^
2025-10-10 20:03:59.945 |   File "/usr/local/lib/python3.11/site-packages/flask/app.py", line 1510, in wsgi_app
2025-10-10 20:03:59.945 |     ctx.push()
2025-10-10 20:03:59.945 |   File "/usr/local/lib/python3.11/site-packages/flask/ctx.py", line 386, in push
2025-10-10 20:03:59.945 |     self.session = session_interface.open_session(self.app, self.request)
2025-10-10 20:03:59.945 |                    ^^^^^^^^^^^^^^^^^^^^^^^^^^^^^^^^^^^^^^^^^^^^^^^^^^^^^^
2025-10-10 20:03:59.945 |   File "/usr/local/lib/python3.11/site-packages/flask_session/base.py", line 350, in open_session
2025-10-10 20:03:59.945 |     saved_session_data = self._retrieve_session_data(store_id)
2025-10-10 20:03:59.945 |                          ^^^^^^^^^^^^^^^^^^^^^^^^^^^^^^^^^^^^^
2025-10-10 20:03:59.945 |   File "/usr/local/lib/python3.11/site-packages/flask_session/redis/redis.py", line 64, in _retrieve_session_data
2025-10-10 20:03:59.945 |     serialized_session_data = self.client.get(store_id)
2025-10-10 20:03:59.945 |                               ^^^^^^^^^^^^^^^^^^^^^^^^^
2025-10-10 20:03:59.945 |   File "/usr/local/lib/python3.11/site-packages/redis/commands/core.py", line 1829, in get
2025-10-10 20:03:59.945 |     return self.execute_command("GET", name, keys=[name])
2025-10-10 20:03:59.945 |            ^^^^^^^^^^^^^^^^^^^^^^^^^^^^^^^^^^^^^^^^^^^^^^
2025-10-10 20:03:59.945 |   File "/usr/local/lib/python3.11/site-packages/redis/client.py", line 621, in execute_command
2025-10-10 20:03:59.945 |     return self._execute_command(*args, **options)
2025-10-10 20:03:59.945 |            ^^^^^^^^^^^^^^^^^^^^^^^^^^^^^^^^^^^^^^^
2025-10-10 20:03:59.945 |   File "/usr/local/lib/python3.11/site-packages/redis/client.py", line 627, in _execute_command
2025-10-10 20:03:59.945 |     conn = self.connection or pool.get_connection()
2025-10-10 20:03:59.945 |                               ^^^^^^^^^^^^^^^^^^^^^
2025-10-10 20:03:59.945 |   File "/usr/local/lib/python3.11/site-packages/redis/utils.py", line 195, in wrapper
2025-10-10 20:03:59.945 |     return func(*args, **kwargs)
2025-10-10 20:03:59.945 |            ^^^^^^^^^^^^^^^^^^^^^
2025-10-10 20:03:59.945 |   File "/usr/local/lib/python3.11/site-packages/redis/connection.py", line 1533, in get_connection
2025-10-10 20:03:59.945 |     connection.connect()
2025-10-10 20:03:59.945 |   File "/usr/local/lib/python3.11/site-packages/redis/connection.py", line 380, in connect
2025-10-10 20:03:59.945 |     self.connect_check_health(check_health=True)
2025-10-10 20:03:59.945 |   File "/usr/local/lib/python3.11/site-packages/redis/connection.py", line 397, in connect_check_health
2025-10-10 20:03:59.945 |     raise ConnectionError(self._error_message(e))
2025-10-10 20:03:59.945 | redis.exceptions.ConnectionError: Error 111 connecting to localhost:6379. Connection refused.
2025-10-10 20:04:09.169 | [2025-10-11 01:04:09 +0000] [6] [ERROR] Error handling request /
2025-10-10 20:04:09.169 | Traceback (most recent call last):
2025-10-10 20:04:09.169 |   File "/usr/local/lib/python3.11/site-packages/redis/connection.py", line 389, in connect_check_health
2025-10-10 20:04:09.169 |     sock = self.retry.call_with_retry(
2025-10-10 20:04:09.169 |            ^^^^^^^^^^^^^^^^^^^^^^^^^^^
2025-10-10 20:04:09.169 |   File "/usr/local/lib/python3.11/site-packages/redis/retry.py", line 105, in call_with_retry
2025-10-10 20:04:09.169 |     return do()
2025-10-10 20:04:09.169 |            ^^^^
2025-10-10 20:04:09.169 |   File "/usr/local/lib/python3.11/site-packages/redis/connection.py", line 390, in <lambda>
2025-10-10 20:04:09.169 |     lambda: self._connect(), lambda error: self.disconnect(error)
2025-10-10 20:04:09.169 |             ^^^^^^^^^^^^^^^
2025-10-10 20:04:09.169 |   File "/usr/local/lib/python3.11/site-packages/redis/connection.py", line 803, in _connect
2025-10-10 20:04:09.169 |     raise err
2025-10-10 20:04:09.169 |   File "/usr/local/lib/python3.11/site-packages/redis/connection.py", line 787, in _connect
2025-10-10 20:04:09.169 |     sock.connect(socket_address)
2025-10-10 20:04:09.170 | ConnectionRefusedError: [Errno 111] Connection refused
2025-10-10 20:04:09.170 | 
2025-10-10 20:04:09.170 | During handling of the above exception, another exception occurred:
2025-10-10 20:04:09.170 | 
2025-10-10 20:04:09.170 | Traceback (most recent call last):
2025-10-10 20:04:09.170 |   File "/usr/local/lib/python3.11/site-packages/gunicorn/workers/sync.py", line 134, in handle
2025-10-10 20:04:09.170 |     self.handle_request(listener, req, client, addr)
2025-10-10 20:04:09.170 |   File "/usr/local/lib/python3.11/site-packages/gunicorn/workers/sync.py", line 177, in handle_request
2025-10-10 20:04:09.170 |     respiter = self.wsgi(environ, resp.start_response)
2025-10-10 20:04:09.170 |                ^^^^^^^^^^^^^^^^^^^^^^^^^^^^^^^^^^^^^^^
2025-10-10 20:04:09.170 |   File "/usr/local/lib/python3.11/site-packages/flask/app.py", line 1536, in __call__
2025-10-10 20:04:09.170 |     return self.wsgi_app(environ, start_response)
2025-10-10 20:04:09.170 |            ^^^^^^^^^^^^^^^^^^^^^^^^^^^^^^^^^^^^^^
2025-10-10 20:04:09.170 |   File "/usr/local/lib/python3.11/site-packages/flask_socketio/__init__.py", line 42, in __call__
2025-10-10 20:04:09.170 |     return super().__call__(environ, start_response)
2025-10-10 20:04:09.170 |            ^^^^^^^^^^^^^^^^^^^^^^^^^^^^^^^^^^^^^^^^^
2025-10-10 20:04:09.170 |   File "/usr/local/lib/python3.11/site-packages/engineio/middleware.py", line 74, in __call__
2025-10-10 20:04:09.170 |     return self.wsgi_app(environ, start_response)
2025-10-10 20:04:09.170 |            ^^^^^^^^^^^^^^^^^^^^^^^^^^^^^^^^^^^^^^
2025-10-10 20:04:09.170 |   File "/usr/local/lib/python3.11/site-packages/flask/app.py", line 1514, in wsgi_app
2025-10-10 20:04:09.170 |     response = self.handle_exception(e)
2025-10-10 20:04:09.170 |                ^^^^^^^^^^^^^^^^^^^^^^^^
2025-10-10 20:04:09.170 |   File "/usr/local/lib/python3.11/site-packages/flask_cors/extension.py", line 176, in wrapped_function
2025-10-10 20:04:09.170 |     return cors_after_request(app.make_response(f(*args, **kwargs)))
2025-10-10 20:04:09.170 |                                                 ^^^^^^^^^^^^^^^^^^
2025-10-10 20:04:09.170 |   File "/usr/local/lib/python3.11/site-packages/flask/app.py", line 1510, in wsgi_app
2025-10-10 20:04:09.170 |     ctx.push()
2025-10-10 20:04:09.170 |   File "/usr/local/lib/python3.11/site-packages/flask/ctx.py", line 386, in push
2025-10-10 20:04:09.170 |     self.session = session_interface.open_session(self.app, self.request)
2025-10-10 20:04:09.170 |                    ^^^^^^^^^^^^^^^^^^^^^^^^^^^^^^^^^^^^^^^^^^^^^^^^^^^^^^
2025-10-10 20:04:09.170 |   File "/usr/local/lib/python3.11/site-packages/flask_session/base.py", line 350, in open_session
2025-10-10 20:04:09.170 |     saved_session_data = self._retrieve_session_data(store_id)
2025-10-10 20:04:09.170 |                          ^^^^^^^^^^^^^^^^^^^^^^^^^^^^^^^^^^^^^
2025-10-10 20:04:09.170 |   File "/usr/local/lib/python3.11/site-packages/flask_session/redis/redis.py", line 64, in _retrieve_session_data
2025-10-10 20:04:09.170 |     serialized_session_data = self.client.get(store_id)
2025-10-10 20:04:09.170 |                               ^^^^^^^^^^^^^^^^^^^^^^^^^
2025-10-10 20:04:09.170 |   File "/usr/local/lib/python3.11/site-packages/redis/commands/core.py", line 1829, in get
2025-10-10 20:04:09.170 |     return self.execute_command("GET", name, keys=[name])
2025-10-10 20:04:09.170 |            ^^^^^^^^^^^^^^^^^^^^^^^^^^^^^^^^^^^^^^^^^^^^^^
2025-10-10 20:04:09.170 |   File "/usr/local/lib/python3.11/site-packages/redis/client.py", line 621, in execute_command
2025-10-10 20:04:09.170 |     return self._execute_command(*args, **options)
2025-10-10 20:04:09.170 |            ^^^^^^^^^^^^^^^^^^^^^^^^^^^^^^^^^^^^^^^
2025-10-10 20:04:09.170 |   File "/usr/local/lib/python3.11/site-packages/redis/client.py", line 627, in _execute_command
2025-10-10 20:04:09.170 |     conn = self.connection or pool.get_connection()
2025-10-10 20:04:09.170 |                               ^^^^^^^^^^^^^^^^^^^^^
2025-10-10 20:04:09.170 |   File "/usr/local/lib/python3.11/site-packages/redis/utils.py", line 195, in wrapper
2025-10-10 20:04:09.170 |     return func(*args, **kwargs)
2025-10-10 20:04:09.170 |            ^^^^^^^^^^^^^^^^^^^^^
2025-10-10 20:04:09.170 |   File "/usr/local/lib/python3.11/site-packages/redis/connection.py", line 1533, in get_connection
2025-10-10 20:04:09.170 |     connection.connect()
2025-10-10 20:04:09.170 |   File "/usr/local/lib/python3.11/site-packages/redis/connection.py", line 380, in connect
2025-10-10 20:04:09.170 |     self.connect_check_health(check_health=True)
2025-10-10 20:04:09.170 |   File "/usr/local/lib/python3.11/site-packages/redis/connection.py", line 397, in connect_check_health
2025-10-10 20:04:09.170 |     raise ConnectionError(self._error_message(e))
2025-10-10 20:04:09.170 | redis.exceptions.ConnectionError: Error 111 connecting to localhost:6379. Connection refused.
2025-10-10 20:04:09.233 | [2025-10-11 01:04:09 +0000] [6] [ERROR] Error handling request /.well-known/appspecific/com.chrome.devtools.json
2025-10-10 20:04:09.233 | Traceback (most recent call last):
2025-10-10 20:04:09.233 |   File "/usr/local/lib/python3.11/site-packages/redis/connection.py", line 389, in connect_check_health
2025-10-10 20:04:09.233 |     sock = self.retry.call_with_retry(
2025-10-10 20:04:09.233 |            ^^^^^^^^^^^^^^^^^^^^^^^^^^^
2025-10-10 20:04:09.233 |   File "/usr/local/lib/python3.11/site-packages/redis/retry.py", line 105, in call_with_retry
2025-10-10 20:04:09.233 |     return do()
2025-10-10 20:04:09.233 |            ^^^^
2025-10-10 20:04:09.233 |   File "/usr/local/lib/python3.11/site-packages/redis/connection.py", line 390, in <lambda>
2025-10-10 20:04:09.233 |     lambda: self._connect(), lambda error: self.disconnect(error)
2025-10-10 20:04:09.233 |             ^^^^^^^^^^^^^^^
2025-10-10 20:04:09.233 |   File "/usr/local/lib/python3.11/site-packages/redis/connection.py", line 803, in _connect
2025-10-10 20:04:09.233 |     raise err
2025-10-10 20:04:09.233 |   File "/usr/local/lib/python3.11/site-packages/redis/connection.py", line 787, in _connect
2025-10-10 20:04:09.233 |     sock.connect(socket_address)
2025-10-10 20:04:09.233 | ConnectionRefusedError: [Errno 111] Connection refused
2025-10-10 20:04:09.233 | 
2025-10-10 20:04:09.233 | During handling of the above exception, another exception occurred:
2025-10-10 20:04:09.233 | 
2025-10-10 20:04:09.233 | Traceback (most recent call last):
2025-10-10 20:04:09.233 |   File "/usr/local/lib/python3.11/site-packages/gunicorn/workers/sync.py", line 134, in handle
2025-10-10 20:04:09.233 |     self.handle_request(listener, req, client, addr)
2025-10-10 20:04:09.233 |   File "/usr/local/lib/python3.11/site-packages/gunicorn/workers/sync.py", line 177, in handle_request
2025-10-10 20:04:09.233 |     respiter = self.wsgi(environ, resp.start_response)
2025-10-10 20:04:09.233 |                ^^^^^^^^^^^^^^^^^^^^^^^^^^^^^^^^^^^^^^^
2025-10-10 20:04:09.233 |   File "/usr/local/lib/python3.11/site-packages/flask/app.py", line 1536, in __call__
2025-10-10 20:04:09.233 |     return self.wsgi_app(environ, start_response)
2025-10-10 20:04:09.233 |            ^^^^^^^^^^^^^^^^^^^^^^^^^^^^^^^^^^^^^^
2025-10-10 20:04:09.233 |   File "/usr/local/lib/python3.11/site-packages/flask_socketio/__init__.py", line 42, in __call__
2025-10-10 20:04:09.233 |     return super().__call__(environ, start_response)
2025-10-10 20:04:09.233 |            ^^^^^^^^^^^^^^^^^^^^^^^^^^^^^^^^^^^^^^^^^
2025-10-10 20:04:09.233 |   File "/usr/local/lib/python3.11/site-packages/engineio/middleware.py", line 74, in __call__
2025-10-10 20:04:09.233 |     return self.wsgi_app(environ, start_response)
2025-10-10 20:04:09.234 |            ^^^^^^^^^^^^^^^^^^^^^^^^^^^^^^^^^^^^^^
2025-10-10 20:04:09.234 |   File "/usr/local/lib/python3.11/site-packages/flask/app.py", line 1514, in wsgi_app
2025-10-10 20:04:09.234 |     response = self.handle_exception(e)
2025-10-10 20:04:09.234 |                ^^^^^^^^^^^^^^^^^^^^^^^^
2025-10-10 20:04:09.234 |   File "/usr/local/lib/python3.11/site-packages/flask_cors/extension.py", line 176, in wrapped_function
2025-10-10 20:04:09.234 |     return cors_after_request(app.make_response(f(*args, **kwargs)))
2025-10-10 20:04:09.234 |                                                 ^^^^^^^^^^^^^^^^^^
2025-10-10 20:04:09.234 |   File "/usr/local/lib/python3.11/site-packages/flask/app.py", line 1510, in wsgi_app
2025-10-10 20:04:09.234 |     ctx.push()
2025-10-10 20:04:09.234 |   File "/usr/local/lib/python3.11/site-packages/flask/ctx.py", line 386, in push
2025-10-10 20:04:09.234 |     self.session = session_interface.open_session(self.app, self.request)
2025-10-10 20:04:09.234 |                    ^^^^^^^^^^^^^^^^^^^^^^^^^^^^^^^^^^^^^^^^^^^^^^^^^^^^^^
2025-10-10 20:04:09.234 |   File "/usr/local/lib/python3.11/site-packages/flask_session/base.py", line 350, in open_session
2025-10-10 20:04:09.234 |     saved_session_data = self._retrieve_session_data(store_id)
2025-10-10 20:04:09.234 |                          ^^^^^^^^^^^^^^^^^^^^^^^^^^^^^^^^^^^^^
2025-10-10 20:04:09.234 |   File "/usr/local/lib/python3.11/site-packages/flask_session/redis/redis.py", line 64, in _retrieve_session_data
2025-10-10 20:04:09.234 |     serialized_session_data = self.client.get(store_id)
2025-10-10 20:04:09.234 |                               ^^^^^^^^^^^^^^^^^^^^^^^^^
2025-10-10 20:04:09.234 |   File "/usr/local/lib/python3.11/site-packages/redis/commands/core.py", line 1829, in get
2025-10-10 20:04:09.234 |     return self.execute_command("GET", name, keys=[name])
2025-10-10 20:04:09.234 |            ^^^^^^^^^^^^^^^^^^^^^^^^^^^^^^^^^^^^^^^^^^^^^^
2025-10-10 20:04:09.234 |   File "/usr/local/lib/python3.11/site-packages/redis/client.py", line 621, in execute_command
2025-10-10 20:04:09.234 |     return self._execute_command(*args, **options)
2025-10-10 20:04:09.234 |            ^^^^^^^^^^^^^^^^^^^^^^^^^^^^^^^^^^^^^^^
2025-10-10 20:04:09.234 |   File "/usr/local/lib/python3.11/site-packages/redis/client.py", line 627, in _execute_command
2025-10-10 20:04:09.234 |     conn = self.connection or pool.get_connection()
2025-10-10 20:04:09.234 |                               ^^^^^^^^^^^^^^^^^^^^^
2025-10-10 20:04:09.234 |   File "/usr/local/lib/python3.11/site-packages/redis/utils.py", line 195, in wrapper
2025-10-10 20:04:09.234 |     return func(*args, **kwargs)
2025-10-10 20:04:09.234 |            ^^^^^^^^^^^^^^^^^^^^^
2025-10-10 20:04:09.234 |   File "/usr/local/lib/python3.11/site-packages/redis/connection.py", line 1533, in get_connection
2025-10-10 20:04:09.234 |     connection.connect()
2025-10-10 20:04:09.234 |   File "/usr/local/lib/python3.11/site-packages/redis/connection.py", line 380, in connect
2025-10-10 20:04:09.234 |     self.connect_check_health(check_health=True)
2025-10-10 20:04:09.234 |   File "/usr/local/lib/python3.11/site-packages/redis/connection.py", line 397, in connect_check_health
2025-10-10 20:04:09.234 |     raise ConnectionError(self._error_message(e))
2025-10-10 20:04:09.234 | redis.exceptions.ConnectionError: Error 111 connecting to localhost:6379. Connection refused.